Workbook

Sheet Build Manifest
A1: SODA Build Manifest
A2: A product of Equalpoint, Inc. . Living tracker: update Status as items move from Specified to Built
A4: Layer | B4: Item | C4: What it is | D4: Status | E4: Format | F4: Notes | H4: _layerfill
A5: 1. Design Foundation | B5: Color system | C5: Green for action, deep green warm surfaces, near-black canvas, amber timers, purple nudges, red errors | D5: Locked | E5: Spec | F5: One dominant element per screen | H5: 1. Design Foundation
B6: Typography | C6: Condensed display, DM Sans UI, DM Mono metadata | D6: Locked | E6: Spec | H6: 1. Design Foundation
B7: Layout rules | C7: Dark mode only, 8pt grid, 44px touch targets | D7: Locked | E7: Spec | H7: 1. Design Foundation
B8: Brand voice + signature line | C8: "A name tag knows you showed up. SODA knows who you became to the room" | D8: Locked | E8: Spec | F8: No em dashes rule | H8: 1. Design Foundation
B9: Motion layer | C9: 100/300/700ms motion system | D9: Pending | E9: Spec | F9: Deliberately last, after screens confirmed | H9: 1. Design Foundation
A10: 2. Naming & Ownership | B10: Product + platform names | C10: SODA (consumer), Relational OS (engine), Equalpoint (owner) | D10: Locked | E10: Spec | H10: 2. Naming & Ownership
B11: The three acts | C11: The Drop, The Chance, The Nudge | D11: Locked | E11: Spec | H11: 2. Naming & Ownership
B12: Ownership model | C12: Host owns event data, Equalpoint owns platform, brand-agnostic | D12: Locked | E12: Spec | H12: 2. Naming & Ownership
A13: 3. Attendee Screens | B13: Entry QR | C13: Attendee-facing screen | D13: Specified | E13: Spec + prompt | F13: Paste-ready Claude Design prompt | H13: 3. Attendee Screens
B14: Welcome | C14: Attendee-facing screen | D14: Specified | E14: Spec + prompt | F14: Paste-ready Claude Design prompt | H14: 3. Attendee Screens
B15: Sign-In | C15: Attendee-facing screen | D15: Specified | E15: Spec + prompt | F15: Paste-ready Claude Design prompt | H15: 3. Attendee Screens
B16: Photo | C16: Attendee-facing screen | D16: Specified | E16: Spec + prompt | F16: Paste-ready Claude Design prompt | H16: 3. Attendee Screens
B17: Role Chips | C17: Attendee-facing screen | D17: Specified | E17: Spec + prompt | F17: Paste-ready Claude Design prompt | H17: 3. Attendee Screens
B18: Offer Chips | C18: Attendee-facing screen | D18: Specified | E18: Spec + prompt | F18: Paste-ready Claude Design prompt | H18: 3. Attendee Screens
B19: Need Chips | C19: Attendee-facing screen | D19: Specified | E19: Spec + prompt | F19: Paste-ready Claude Design prompt | H19: 3. Attendee Screens
B20: Room View | C20: Attendee-facing screen | D20: Specified | E20: Spec + prompt | F20: Paste-ready Claude Design prompt | H20: 3. Attendee Screens
B21: The Drop | C21: Attendee-facing screen | D21: Specified | E21: Spec + prompt | F21: Paste-ready Claude Design prompt | H21: 3. Attendee Screens
B22: The Chance | C22: Attendee-facing screen | D22: Specified | E22: Spec + prompt | F22: Paste-ready Claude Design prompt | H22: 3. Attendee Screens
B23: The Nudge | C23: Attendee-facing screen | D23: Specified | E23: Spec + prompt | F23: Paste-ready Claude Design prompt | H23: 3. Attendee Screens
B24: Returning-Guest Recognition | C24: Attendee-facing screen | D24: Specified | E24: Spec + prompt | F24: Paste-ready Claude Design prompt | H24: 3. Attendee Screens
B25: The Comment | C25: Attendee-facing screen | D25: Specified | E25: Spec + prompt | F25: Paste-ready Claude Design prompt | H25: 3. Attendee Screens
... B29: Recap Email | C29: Attendee-facing screen | D29: Specified | E29: Spec + prompt | F29: Paste-ready Claude Design prompt | H29: 3. Attendee Screens
A30: 4. Host - Admin | B30: Event Creation | C30: Admin back-office component | D30: Specified | E30: Spec | H30: 4. Host - Admin
B31: Host Identity & Branding | C31: Admin back-office component | D31: Specified | E31: Spec | H31: 4. Host - Admin
B32: Event Setup / Active Event | C32: Admin back-office component | D32: Specified | E32: Spec | H32: 4. Host - Admin
B33: Prompt & Pairing Settings | C33: Admin back-office component | D33: Specified | E33: Spec | H33: 4. Host - Admin
B34: Question Creator | C34: Admin back-office component | D34: Specified | E34: Spec | H34: 4. Host - Admin
B35: Chip Queue & Moderation | C35: Admin back-office component | D35: Specified | E35: Spec | H35: 4. Host - Admin
B36: Check-In Panel | C36: Admin back-office component | D36: Specified | E36: Spec | H36: 4. Host - Admin
B37: Lifecycle Control | C37: Admin back-office component | D37: Specified | E37: Spec | H37: 4. Host - Admin
B38: Matches Panel | C38: Admin back-office component | D38: Specified | E38: Spec | H38: 4. Host - Admin
B39: Survey Panel | C39: Admin back-office component | D39: Specified | E39: Spec | H39: 4. Host - Admin
B40: Export Panel | C40: Admin back-office component | D40: Specified | E40: Spec | H40: 4. Host - Admin
A41: 4. Host - Command Center | B41: Live Stat Bar | C41: Live cockpit component | D41: Specified | E41: Spec | H41: 4. Host - Command Center
B42: Activity Feed | C42: Live cockpit component | D42: Specified | E42: Spec | H42: 4. Host - Command Center
B43: Connection Status Badge | C43: Live cockpit component | D43: Specified | E43: Spec | H43: 4. Host - Command Center
B44: Room View (Host) | C44: Live cockpit component | D44: Specified | E44: Spec | H44: 4. Host - Command Center
...

Sheet Summary
A1: Status Snapshot
A3: Total items | B3: =COUNTA('Build Manifest'!B5:B109) -> 105
A5: By status | D5: By layer
A6: Locked | B6: =COUNTIF('Build Manifest'!D5:D109,"Locked") -> 7 | D6: 1. Design Foundation | E6: =COUNTIF('Build Manifest'!H5:H109,"1. Design Foundation") -> 5
A7: Specified | B7: =COUNTIF('Build Manifest'!D5:D109,"Specified") -> 74 | D7: 2. Naming & Ownership | E7: =COUNTIF('Build Manifest'!H5:H109,"2. Naming & Ownership") -> 3
A8: Built | B8: =COUNTIF('Build Manifest'!D5:D109,"Built") -> 5 | D8: 3. Attendee Screens | E8: =COUNTIF('Build Manifest'!H5:H109,"3. Attendee Screens") -> 17
A9: Prototyped | B9: =COUNTIF('Build Manifest'!D5:D109,"Prototyped") -> 4 | D9: 4. Host - Admin | E9: =COUNTIF('Build Manifest'!H5:H109,"4. Host - Admin") -> 11
A10: Drafted | B10: =COUNTIF('Build Manifest'!D5:D109,"Drafted") -> 5 | D10: 4. Host - Command Center | E10: =COUNTIF('Build Manifest'!H5:H109,"4. Host - Command Center") -> 11
A11: Reserved | B11: =COUNTIF('Build Manifest'!D5:D109,"Reserved") -> 5 | D11: 4. Host - Access | E11: =COUNTIF('Build Manifest'!H5:H109,"4. Host - Access") -> 10
A12: Parked | B12: =COUNTIF('Build Manifest'!D5:D109,"Parked") -> 0 | D12: 5. Home & Profile | E12: =COUNTIF('Build Manifest'!H5:H109,"5. Home & Profile") -> 6
A13: Pending | B13: =COUNTIF('Build Manifest'!D5:D109,"Pending") -> 5 | D13: 6. Event Layer | E13: =COUNTIF('Build Manifest'!H5:H109,"6. Event Layer") -> 4
D14: 7. States | E14: =COUNTIF('Build Manifest'!H5:H109,"7. States") -> 3
D15: 8. Auth, Sessions & Failures | E15: =COUNTIF('Build Manifest'!H5:H109,"8. Auth, Sessions & Failures") -> 9
A16: Headline numbers | D16: 9. Component Inventory | E16: =COUNTIF('Build Manifest'!H5:H109,"9. Component Inventory") -> 2
A17: Attendee screens specified | B17: 16 | D17: 10. Flow Maps | E17: =COUNTIF('Build Manifest'!H5:H109,"10. Flow Maps") -> 4
A18: Home screens specified | B18: 4 | D18: 11. Prototypes | E18: =COUNTIF('Build Manifest'!H5:H109,"11. Prototypes") -> 3
A19: Components in inventory | B19: 78 | D19: 12. Technical Architecture | E19: =COUNTIF('Build Manifest'!H5:H109,"12. Technical Architecture") -> 7
A20: Empty / loading / error states | B20: 31 | D20: 13. Legal & Trust | E20: =COUNTIF('Build Manifest'!H5:H109,"13. Legal & Trust") -> 2
A21: Flow maps built | B21: 3 | D21: 14. Decks | E21: =COUNTIF('Build Manifest'!H5:H109,"14. Decks") -> 3
A22: Decks drafted | B22: 3 | D22: 15. Reserved (Soon) | E22: =COUNTIF('Build Manifest'!H5:H109,"15. Reserved (Soon)") -> 3
D23: 16. App Build | E23: =COUNTIF('Build Manifest'!H5:H109,"16. App Build") -> 2
A24: Legend: Locked = settled . Specified = spec + prompt ready . Built = artifact exists . Prototyped = working sim . Drafted = draft for review . Reserved/Parked = intentionally later . Pending = to do
